Workbook

Sheet Start Here
B2: BAR CONTROL SYSTEM
B3: A spreadsheet version of your Control Report — warehouse, bar (snack), sales, and business trend.
B5: DAILY ROUTINE
B6: Every closing | C6: Go to Daily Entry. Add one row per drink for that date. Type warehouse opening/purchase/crates sent, bar opening qty and the bar closing count. Sold qty, sales and profit calculate themselves.
B7: Then | C7: Go to Daily Cash, add that date, and type expenses, damages, shortage and debt. Balance Sales is the cash the bar tender should hand over.
B8: To print | C8: Open Control Report, change the yellow date at the top, and print. It is the same layout as your paper form, signature lines included.
B10: THE SHEETS
B11: Drinks | C11: Master list: units per crate, buying price per crate, selling price per unit. Everything reads from here.
B12: Daily Entry | C12: The engine. One row per drink per day. 2,000 rows.
B13: Daily Cash | C13: Your Control Sheet of Business Trend, one row per day.
B14: Control Report | C14: Printable form for any single date.
B15: Dashboard | C15: Any date range: sales, profit, deductions, and which drinks actually make you money.
B17: THE FORMULAS BEHIND IT
B18: Warehouse closing | C18: Opening Crates + Purchase - Crates Sent to Bar
B19: Bar supply | C19: Crates Sent to Bar x Units per Crate (type over it if you sent loose bottles)
B20: Sold | C20: Bar Opening + Supply - Bar Closing count
B21: Sales amount | C21: Sold x Selling Price per unit
B22: Balance sales | C22: Sales + Recovered - Damaged - Expenses - Shortage - Debt
B23: Net profit | C23: Gross Profit - Damaged - Expenses - Shortage
B25: PRICES
B26: Source | C26: Buying prices and crate sizes come from your Magazine Rate list of 31 products. Every margin is positive and between 13 and 58 percent.
B27: Selling prices | C27: Carried over from the 22 August control report. Confirm them: only Big Guinness, Big Smooth and Heineken are at 1,500, Supper Mount and Reaktor at 500, everything else at 1,000.
B28: Thinnest margin | C28: Small Smooth at 133 a bottle (13 percent), because a crate holds 15. Worth a second look.
B29: Best margin | C29: Top Tonic at 583 a bottle (58 percent), then Supper Mount at 258 on a 500 sale.
B31: WHAT I FOUND IN YOUR 22 AUGUST SHEET
B32: Warehouse double-count | C32: Mutzig, Castle Beer and Isenbeck each show crates purchased AND still sitting in warehouse closing, yet the same crates appear as bar supply (72, 60, 60 units). The crates cannot be in both places. In this workbook I entered them as sent to the bar, so warehouse closing is 0.
B33: Castle Beer row | C33: The row reads 14 sold / 14,000, but 16 + 60 - 57 = 19 sold = 19,000. Your own column total of 272,500 only works if it is 19,000 — so the 14 is a slip of the pen, not a stock loss. This workbook uses 19,000 and ties to your 272,500 exactly.
B34: Castle Milk amount | C34: 4 crates closing x 5,500 = 22,000, but the sheet shows 34,000.
B35: Carry-over check | C35: Daily Entry column S compares each day's opening against the previous day's closing and turns red on a mismatch. That is your shortage detector.
B37: HOUSEKEEPING
B38: Currency | C38: Whole numbers, no decimals, matching your sheet. Format > Cells > Currency to add FCFA.
B39: Grey rows | C39: The 22 August data is pre-loaded as a worked example. Delete those rows once you are comfortable.
B40: Backup | C40: Save a dated copy every week.

Sheet Drinks
A1: DRINKS MASTER LIST
A2: Every other sheet reads from here. Blue = you type. Check every Buying Price and Units per Crate before you rely on the profit figures.
A3: Drink | B3: Units per Crate | C3: Buying Price (per crate) | D3: Buying Price (per unit) | E3: Selling Price (per unit) | F3: Profit per Unit | G3: Margin %
A4: Doppel | B4: 12 | C4: 8500 | D4: =IF(OR($A4="",$B4=0),"",$C4/$B4) -> 708.33333 | E4: 1000 | F4: =IF($A4="","",$E4-$D4) -> 291.66667 | G4: =IF(OR($A4="",$E4=0),"",($E4-$D4)/$E4) -> 0.29166667
A5: Mutzig | B5: 12 | C5: 8500 | D5: =IF(OR($A5="",$B5=0),"",$C5/$B5) -> 708.33333 | E5: 1000 | F5: =IF($A5="","",$E5-$D5) -> 291.66667 | G5: =IF(OR($A5="",$E5=0),"",($E5-$D5)/$E5) -> 0.29166667
A6: Export | B6: 12 | C6: 8500 | D6: =IF(OR($A6="",$B6=0),"",$C6/$B6) -> 708.33333 | E6: 1000 | F6: =IF($A6="","",$E6-$D6) -> 291.66667 | G6: =IF(OR($A6="",$E6=0),"",($E6-$D6)/$E6) -> 0.29166667
A7: Castel Beer | B7: 12 | C7: 8500 | D7: =IF(OR($A7="",$B7=0),"",$C7/$B7) -> 708.33333 | E7: 1000 | F7: =IF($A7="","",$E7-$D7) -> 291.66667 | G7: =IF(OR($A7="",$E7=0),"",($E7-$D7)/$E7) -> 0.29166667
A8: Castel Milk | B8: 12 | C8: 8500 | D8: =IF(OR($A8="",$B8=0),"",$C8/$B8) -> 708.33333 | E8: 1000 | F8: =IF($A8="","",$E8-$D8) -> 291.66667 | G8: =IF(OR($A8="",$E8=0),"",($E8-$D8)/$E8) -> 0.29166667
A9: Beaufort Light | B9: 12 | C9: 8500 | D9: =IF(OR($A9="",$B9=0),"",$C9/$B9) -> 708.33333 | E9: 1000 | F9: =IF($A9="","",$E9-$D9) -> 291.66667 | G9: =IF(OR($A9="",$E9=0),"",($E9-$D9)/$E9) -> 0.29166667
A10: Beaufort Lager | B10: 12 | C10: 8500 | D10: =IF(OR($A10="",$B10=0),"",$C10/$B10) -> 708.33333 | E10: 1000 | F10: =IF($A10="","",$E10-$D10) -> 291.66667 | G10: =IF(OR($A10="",$E10=0),"",($E10-$D10)/$E10) -> 0.29166667
A11: World Cola | B11: 6 | C11: 4000 | D11: =IF(OR($A11="",$B11=0),"",$C11/$B11) -> 666.66667 | E11: 1000 | F11: =IF($A11="","",$E11-$D11) -> 333.33333 | G11: =IF(OR($A11="",$E11=0),"",($E11-$D11)/$E11) -> 0.33333333
A12: Sprite | B12: 6 | C12: 4000 | D12: =IF(OR($A12="",$B12=0),"",$C12/$B12) -> 666.66667 | E12: 1000 | F12: =IF($A12="","",$E12-$D12) -> 333.33333 | G12: =IF(OR($A12="",$E12=0),"",($E12-$D12)/$E12) -> 0.33333333
A13: Isenbeck | B13: 12 | C13: 9500 | D13: =IF(OR($A13="",$B13=0),"",$C13/$B13) -> 791.66667 | E13: 1000 | F13: =IF($A13="","",$E13-$D13) -> 208.33333 | G13: =IF(OR($A13="",$E13=0),"",($E13-$D13)/$E13) -> 0.20833333
A14: Booster Cola | B14: 12 | C14: 8500 | D14: =IF(OR($A14="",$B14=0),"",$C14/$B14) -> 708.33333 | E14: 1000 | F14: =IF($A14="","",$E14-$D14) -> 291.66667 | G14: =IF(OR($A14="",$E14=0),"",($E14-$D14)/$E14) -> 0.29166667
A15: Booster Gin | B15: 12 | C15: 8500 | D15: =IF(OR($A15="",$B15=0),"",$C15/$B15) -> 708.33333 | E15: 1000 | F15: =IF($A15="","",$E15-$D15) -> 291.66667 | G15: =IF(OR($A15="",$E15=0),"",($E15-$D15)/$E15) -> 0.29166667
... A34: Reaktor | B34: 12 | C34: 4300 | D34: =IF(OR($A34="",$B34=0),"",$C34/$B34) -> 358.33333 | E34: 500 | F34: =IF($A34="","",$E34-$D34) -> 141.66667 | G34: =IF(OR($A34="",$E34=0),"",($E34-$D34)/$E34) -> 0.28333333
D35: =IF(OR($A35="",$B35=0),"",$C35/$B35) | F35: =IF($A35="","",$E35-$D35) | G35: =IF(OR($A35="",$E35=0),"",($E35-$D35)/$E35)
D36: =IF(OR($A36="",$B36=0),"",$C36/$B36) | F36: =IF($A36="","",$E36-$D36) | G36: =IF(OR($A36="",$E36=0),"",($E36-$D36)/$E36)
D37: =IF(OR($A37="",$B37=0),"",$C37/$B37) | F37: =IF($A37="","",$E37-$D37) | G37: =IF(OR($A37="",$E37=0),"",($E37-$D37)/$E37)
D38: =IF(OR($A38="",$B38=0),"",$C38/$B38) | F38: =IF($A38="","",$E38-$D38) | G38: =IF(OR($A38="",$E38=0),"",($E38-$D38)/$E38)
D39: =IF(OR($A39="",$B39=0),"",$C39/$B39) | F39: =IF($A39="","",$E39-$D39) | G39: =IF(OR($A39="",$E39=0),"",($E39-$D39)/$E39)
D40: =IF(OR($A40="",$B40=0),"",$C40/$B40) | F40: =IF($A40="","",$E40-$D40) | G40: =IF(OR($A40="",$E40=0),"",($E40-$D40)/$E40)
D41: =IF(OR($A41="",$B41=0),"",$C41/$B41) | F41: =IF($A41="","",$E41-$D41) | G41: =IF(OR($A41="",$E41=0),"",($E41-$D41)/$E41)
D42: =IF(OR($A42="",$B42=0),"",$C42/$B42) | F42: =IF($A42="","",$E42-$D42) | G42: =IF(OR($A42="",$E42=0),"",($E42-$D42)/$E42)
D43: =IF(OR($A43="",$B43=0),"",$C43/$B43) | F43: =IF($A43="","",$E43-$D43) | G43: =IF(OR($A43="",$E43=0),"",($E43-$D43)/$E43)
D44: =IF(OR($A44="",$B44=0),"",$C44/$B44) | F44: =IF($A44="","",$E44-$D44) | G44: =IF(OR($A44="",$E44=0),"",($E44-$D44)/$E44)
D45: =IF(OR($A45="",$B45=0),"",$C45/$B45) | F45: =IF($A45="","",$E45-$D45) | G45: =IF(OR($A45="",$E45=0),"",($E45-$D45)/$E45)
D46: =IF(OR($A46="",$B46=0),"",$C46/$B46) | F46: =IF($A46="","",$E46-$D46) | G46: =IF(OR($A46="",$E46=0),"",($E46-$D46)/$E46)
... D53: =IF(OR($A53="",$B53=0),"",$C53/$B53) | F53: =IF($A53="","",$E53-$D53) | G53: =IF(OR($A53="",$E53=0),"",($E53-$D53)/$E53)

Sheet Daily Entry
A1: DAILY ENTRY — one row per drink, per day
A2: Type the BLUE columns only: Date, Drink, warehouse opening/purchase/crates sent, bar opening, and bar closing count. Everything else calculates.
C3: STOCK AT WAREHOUSE (crates / pallets) | J3: STOCK AT BAR (SNACK) — units
A4: 46256 | B4: Export | C4: 5 | D4: 0 | E4: 5 | F4: =IF($B4="","",$C4+$D4-$E4) -> 0 | G4: =IF($B4="","",IFERROR(INDEX(Drinks!$C$4:$C$53,MATCH($B4,Drinks!$A$4:$A$53,0)),0)) -> 8500 | H4: =IF($B4="","",$D4*$G4) -> 0 | I4: =IF($B4="","",$F4*$G4) -> 0 | J4: 27 | K4: =IF($B4="","",$E4*IFERROR(INDEX(Drinks!$B$4:$B$53,MATCH($B4,Drinks!$A$4:$A$53,0)),0)) -> 60 | L4: =IF($B4="","",$J4+$K4) -> 87 | M4: 27 | N4: =IF($B4="","",$L4-$M4) -> 60 | O4: =IF($B4="","",IFERROR(INDEX(Drinks!$E$4:$E$53,MATCH($B4,Drinks!$A$4:$A$53,0)),0)) -> 1000 | P4: =IF($B4="","",$N4*$O4) -> 60000 | Q4: =IF($B4="","",$N4*IFERROR(INDEX(Drinks!$D$4:$D$53,MATCH($B4,Drinks!$A$4:$A$53,0)),0)) -> 42500 | R4: =IF($B4="","",$P4-$Q4) -> 17500 | S4: =IF($B4="","",IF(COUNTIFS($A$4:$A$2003,$A4-1,$B$4:$B$2003,$B4)=0,"first day",IF(SUMIFS($M$4:$M$2003,$A$4:$A$2003,$A4-1,$B$4:$B$2003,$B4)=$J4,"OK","CHECK"))) -> first day | T4: Buy Price /Unit
A5: 46256 | B5: Mutzig | C5: 0 | D5: 6 | E5: 6 | F5: =IF($B5="","",$C5+$D5-$E5) -> 0 | G5: =IF($B5="","",IFERROR(INDEX(Drinks!$C$4:$C$53,MATCH($B5,Drinks!$A$4:$A$53,0)),0)) -> 8500 | H5: =IF($B5="","",$D5*$G5) -> 51000 | I5: =IF($B5="","",$F5*$G5) -> 0 | J5: 16 | K5: =IF($B5="","",$E5*IFERROR(INDEX(Drinks!$B$4:$B$53,MATCH($B5,Drinks!$A$4:$A$53,0)),0)) -> 72 | L5: =IF($B5="","",$J5+$K5) -> 88 | M5: 73 | N5: =IF($B5="","",$L5-$M5) -> 15 | O5: =IF($B5="","",IFERROR(INDEX(Drinks!$E$4:$E$53,MATCH($B5,Drinks!$A$4:$A$53,0)),0)) -> 1000 | P5: =IF($B5="","",$N5*$O5) -> 15000 | Q5: =IF($B5="","",$N5*IFERROR(INDEX(Drinks!$D$4:$D$53,MATCH($B5,Drinks!$A$4:$A$53,0)),0)) -> 10625 | R5: =IF($B5="","",$P5-$Q5) -> 4375 | S5: =IF($B5="","",IF(COUNTIFS($A$4:$A$2003,$A5-1,$B$4:$B$2003,$B5)=0,"first day",IF(SUMIFS($M$4:$M$2003,$A$4:$A$2003,$A5-1,$B$4:$B$2003,$B5)=$J5,"OK","CHECK"))) -> first day | T5: =IF($B5="","",IFERROR(INDEX(Drinks!$D$4:$D$53,MATCH($B5,Drinks!$A$4:$A$53,0)),0)) -> 708.33333
A6: 46256 | B6: Castel Beer | C6: 0 | D6: 5 | E6: 5 | F6: =IF($B6="","",$C6+$D6-$E6) -> 0 | G6: =IF($B6="","",IFERROR(INDEX(Drinks!$C$4:$C$53,MATCH($B6,Drinks!$A$4:$A$53,0)),0)) -> 8500 | H6: =IF($B6="","",$D6*$G6) -> 42500 | I6: =IF($B6="","",$F6*$G6) -> 0 | J6: 16 | K6: =IF($B6="","",$E6*IFERROR(INDEX(Drinks!$B$4:$B$53,MATCH($B6,Drinks!$A$4:$A$53,0)),0)) -> 60 | L6: =IF($B6="","",$J6+$K6) -> 76 | M6: 57 | N6: =IF($B6="","",$L6-$M6) -> 19 | O6: =IF($B6="","",IFERROR(INDEX(Drinks!$E$4:$E$53,MATCH($B6,Drinks!$A$4:$A$53,0)),0)) -> 1000 | P6: =IF($B6="","",$N6*$O6) -> 19000 | Q6: =IF($B6="","",$N6*IFERROR(INDEX(Drinks!$D$4:$D$53,MATCH($B6,Drinks!$A$4:$A$53,0)),0)) -> 13458.333 | R6: =IF($B6="","",$P6-$Q6) -> 5541.6667 | S6: =IF($B6="","",IF(COUNTIFS($A$4:$A$2003,$A6-1,$B$4:$B$2003,$B6)=0,"first day",IF(SUMIFS($M$4:$M$2003,$A$4:$A$2003,$A6-1,$B$4:$B$2003,$B6)=$J6,"OK","CHECK"))) -> first day | T6: =IF($B6="","",IFERROR(INDEX(Drinks!$D$4:$D$53,MATCH($B6,Drinks!$A$4:$A$53,0)),0)) -> 708.33333
A7: 46256 | B7: Beaufort Light | C7: 1 | D7: 0 | E7: 0 | F7: =IF($B7="","",$C7+$D7-$E7) -> 1 | G7: =IF($B7="","",IFERROR(INDEX(Drinks!$C$4:$C$53,MATCH($B7,Drinks!$A$4:$A$53,0)),0)) -> 8500 | H7: =IF($B7="","",$D7*$G7) -> 0 | I7: =IF($B7="","",$F7*$G7) -> 8500 | J7: 13 | K7: =IF($B7="","",$E7*IFERROR(INDEX(Drinks!$B$4:$B$53,MATCH($B7,Drinks!$A$4:$A$53,0)),0)) -> 0 | L7: =IF($B7="","",$J7+$K7) -> 13 | M7: 5 | N7: =IF($B7="","",$L7-$M7) -> 8 | O7: =IF($B7="","",IFERROR(INDEX(Drinks!$E$4:$E$53,MATCH($B7,Drinks!$A$4:$A$53,0)),0)) -> 1000 | P7: =IF($B7="","",$N7*$O7) -> 8000 | Q7: =IF($B7="","",$N7*IFERROR(INDEX(Drinks!$D$4:$D$53,MATCH($B7,Drinks!$A$4:$A$53,0)),0)) -> 5666.6667 | R7: =IF($B7="","",$P7-$Q7) -> 2333.3333 | S7: =IF($B7="","",IF(COUNTIFS($A$4:$A$2003,$A7-1,$B$4:$B$2003,$B7)=0,"first day",IF(SUMIFS($M$4:$M$2003,$A$4:$A$2003,$A7-1,$B$4:$B$2003,$B7)=$J7,"OK","CHECK"))) -> first day | T7: =IF($B7="","",IFERROR(INDEX(Drinks!$D$4:$D$53,MATCH($B7,Drinks!$A$4:$A$53,0)),0)) -> 708.33333
A8: 46256 | B8: Beaufort Lager | C8: 2 | D8: 0 | E8: 0 | F8: =IF($B8="","",$C8+$D8-$E8) -> 2 | G8: =IF($B8="","",IFERROR(INDEX(Drinks!$C$4:$C$53,MATCH($B8,Drinks!$A$4:$A$53,0)),0)) -> 8500 | H8: =IF($B8="","",$D8*$G8) -> 0 | I8: =IF($B8="","",$F8*$G8) -> 17000 | J8: 9 | K8: =IF($B8="","",$E8*IFERROR(INDEX(Drinks!$B$4:$B$53,MATCH($B8,Drinks!$A$4:$A$53,0)),0)) -> 0 | L8: =IF($B8="","",$J8+$K8) -> 9 | M8: 0 | N8: =IF($B8="","",$L8-$M8) -> 9 | O8: =IF($B8="","",IFERROR(INDEX(Drinks!$E$4:$E$53,MATCH($B8,Drinks!$A$4:$A$53,0)),0)) -> 1000 | P8: =IF($B8="","",$N8*$O8) -> 9000 | Q8: =IF($B8="","",$N8*IFERROR(INDEX(Drinks!$D$4:$D$53,MATCH($B8,Drinks!$A$4:$A$53,0)),0)) -> 6375 | R8: =IF($B8="","",$P8-$Q8) -> 2625 | S8: =IF($B8="","",IF(COUNTIFS($A$4:$A$2003,$A8-1,$B$4:$B$2003,$B8)=0,"first day",IF(SUMIFS($M$4:$M$2003,$A$4:$A$2003,$A8-1,$B$4:$B$2003,$B8)=$J8,"OK","CHECK"))) -> first day | T8: =IF($B8="","",IFERROR(INDEX(Drinks!$D$4:$D$53,MATCH($B8,Drinks!$A$4:$A$53,0)),0)) -> 708.33333
A9: 46256 | B9: Doppel | C9: 0 | D9: 0 | E9: 0 | F9: =IF($B9="","",$C9+$D9-$E9) -> 0 | G9: =IF($B9="","",IFERROR(INDEX(Drinks!$C$4:$C$53,MATCH($B9,Drinks!$A$4:$A$53,0)),0)) -> 8500 | H9: =IF($B9="","",$D9*$G9) -> 0 | I9: =IF($B9="","",$F9*$G9) -> 0 | J9: 7 | K9: =IF($B9="","",$E9*IFERROR(INDEX(Drinks!$B$4:$B$53,MATCH($B9,Drinks!$A$4:$A$53,0)),0)) -> 0 | L9: =IF($B9="","",$J9+$K9) -> 7 | M9: 1 | N9: =IF($B9="","",$L9-$M9) -> 6 | O9: =IF($B9="","",IFERROR(INDEX(Drinks!$E$4:$E$53,MATCH($B9,Drinks!$A$4:$A$53,0)),0)) -> 1000 | P9: =IF($B9="","",$N9*$O9) -> 6000 | Q9: =IF($B9="","",$N9*IFERROR(INDEX(Drinks!$D$4:$D$53,MATCH($B9,Drinks!$A$4:$A$53,0)),0)) -> 4250 | R9: =IF($B9="","",$P9-$Q9) -> 1750 | S9: =IF($B9="","",IF(COUNTIFS($A$4:$A$2003,$A9-1,$B$4:$B$2003,$B9)=0,"first day",IF(SUMIFS($M$4:$M$2003,$A$4:$A$2003,$A9-1,$B$4:$B$2003,$B9)=$J9,"OK","CHECK"))) -> first day | T9: =IF($B9="","",IFERROR(INDEX(Drinks!$D$4:$D$53,MATCH($B9,Drinks!$A$4:$A$53,0)),0)) -> 708.33333
A10: 46256 | B10: Castel Milk | C10: 4 | D10: 3 | E10: 3 | F10: =IF($B10="","",$C10+$D10-$E10) -> 4 | G10: =IF($B10="","",IFERROR(INDEX(Drinks!$C$4:$C$53,MATCH($B10,Drinks!$A$4:$A$53,0)),0)) -> 8500 | H10: =IF($B10="","",$D10*$G10) -> 25500 | I10: =IF($B10="","",$F10*$G10) -> 34000 | J10: 0 | K10: =IF($B10="","",$E10*IFERROR(INDEX(Drinks!$B$4:$B$53,MATCH($B10,Drinks!$A$4:$A$53,0)),0)) -> 36 | L10: =IF($B10="","",$J10+$K10) -> 36 | M10: 34 | N10: =IF($B10="","",$L10-$M10) -> 2 | O10: =IF($B10="","",IFERROR(INDEX(Drinks!$E$4:$E$53,MATCH($B10,Drinks!$A$4:$A$53,0)),0)) -> 1000 | P10: =IF($B10="","",$N10*$O10) -> 2000 | Q10: =IF($B10="","",$N10*IFERROR(INDEX(Drinks!$D$4:$D$53,MATCH($B10,Drinks!$A$4:$A$53,0)),0)) -> 1416.6667 | R10: =IF($B10="","",$P10-$Q10) -> 583.33333 | S10: =IF($B10="","",IF(COUNTIFS($A$4:$A$2003,$A10-1,$B$4:$B$2003,$B10)=0,"first day",IF(SUMIFS($M$4:$M$2003,$A$4:$A$2003,$A10-1,$B$4:$B$2003,$B10)=$J10,"OK","CHECK"))) -> first day | T10: =IF($B10="","",IFERROR(INDEX(Drinks!$D$4:$D$53,MATCH($B10,Drinks!$A$4:$A$53,0)),0)) -> 708.33333
A11: 46256 | B11: World Cola | C11: 0 | D11: 0 | E11: 0 | F11: =IF($B11="","",$C11+$D11-$E11) -> 0 | G11: =IF($B11="","",IFERROR(INDEX(Drinks!$C$4:$C$53,MATCH($B11,Drinks!$A$4:$A$53,0)),0)) -> 4000 | H11: =IF($B11="","",$D11*$G11) -> 0 | I11: =IF($B11="","",$F11*$G11) -> 0 | J11: 1 | K11: =IF($B11="","",$E11*IFERROR(INDEX(Drinks!$B$4:$B$53,MATCH($B11,Drinks!$A$4:$A$53,0)),0)) -> 0 | L11: =IF($B11="","",$J11+$K11) -> 1 | M11: 1 | N11: =IF($B11="","",$L11-$M11) -> 0 | O11: =IF($B11="","",IFERROR(INDEX(Drinks!$E$4:$E$53,MATCH($B11,Drinks!$A$4:$A$53,0)),0)) -> 1000 | P11: =IF($B11="","",$N11*$O11) -> 0 | Q11: =IF($B11="","",$N11*IFERROR(INDEX(Drinks!$D$4:$D$53,MATCH($B11,Drinks!$A$4:$A$53,0)),0)) -> 0 | R11: =IF($B11="","",$P11-$Q11) -> 0 | S11: =IF($B11="","",IF(COUNTIFS($A$4:$A$2003,$A11-1,$B$4:$B$2003,$B11)=0,"first day",IF(SUMIFS($M$4:$M$2003,$A$4:$A$2003,$A11-1,$B$4:$B$2003,$B11)=$J11,"OK","CHECK"))) -> first day | T11: =IF($B11="","",IFERROR(INDEX(Drinks!$D$4:$D$53,MATCH($B11,Drinks!$A$4:$A$53,0)),0)) -> 666.66667
A12: 46256 | B12: Sprite | C12: 1 | D12: 0 | E12: 0 | F12: =IF($B12="","",$C12+$D12-$E12) -> 1 | G12: =IF($B12="","",IFERROR(INDEX(Drinks!$C$4:$C$53,MATCH($B12,Drinks!$A$4:$A$53,0)),0)) -> 4000 | H12: =IF($B12="","",$D12*$G12) -> 0 | I12: =IF($B12="","",$F12*$G12) -> 4000 | J12: 5 | K12: =IF($B12="","",$E12*IFERROR(INDEX(Drinks!$B$4:$B$53,MATCH($B12,Drinks!$A$4:$A$53,0)),0)) -> 0 | L12: =IF($B12="","",$J12+$K12) -> 5 | M12: 5 | N12: =IF($B12="","",$L12-$M12) -> 0 | O12: =IF($B12="","",IFERROR(INDEX(Drinks!$E$4:$E$53,MATCH($B12,Drinks!$A$4:$A$53,0)),0)) -> 1000 | P12: =IF($B12="","",$N12*$O12) -> 0 | Q12: =IF($B12="","",$N12*IFERROR(INDEX(Drinks!$D$4:$D$53,MATCH($B12,Drinks!$A$4:$A$53,0)),0)) -> 0 | R12: =IF($B12="","",$P12-$Q12) -> 0 | S12: =IF($B12="","",IF(COUNTIFS($A$4:$A$2003,$A12-1,$B$4:$B$2003,$B12)=0,"first day",IF(SUMIFS($M$4:$M$2003,$A$4:$A$2003,$A12-1,$B$4:$B$2003,$B12)=$J12,"OK","CHECK"))) -> first day | T12: =IF($B12="","",IFERROR(INDEX(Drinks!$D$4:$D$53,MATCH($B12,Drinks!$A$4:$A$53,0)),0)) -> 666.66667
A13: 46256 | B13: Isenbeck | C13: 0 | D13: 5 | E13: 5 | F13: =IF($B13="","",$C13+$D13-$E13) -> 0 | G13: =IF($B13="","",IFERROR(INDEX(Drinks!$C$4:$C$53,MATCH($B13,Drinks!$A$4:$A$53,0)),0)) -> 9500 | H13: =IF($B13="","",$D13*$G13) -> 47500 | I13: =IF($B13="","",$F13*$G13) -> 0 | J13: 2 | K13: =IF($B13="","",$E13*IFERROR(INDEX(Drinks!$B$4:$B$53,MATCH($B13,Drinks!$A$4:$A$53,0)),0)) -> 60 | L13: =IF($B13="","",$J13+$K13) -> 62 | M13: 45 | N13: =IF($B13="","",$L13-$M13) -> 17 | O13: =IF($B13="","",IFERROR(INDEX(Drinks!$E$4:$E$53,MATCH($B13,Drinks!$A$4:$A$53,0)),0)) -> 1000 | P13: =IF($B13="","",$N13*$O13) -> 17000 | Q13: =IF($B13="","",$N13*IFERROR(INDEX(Drinks!$D$4:$D$53,MATCH($B13,Drinks!$A$4:$A$53,0)),0)) -> 13458.333 | R13: =IF($B13="","",$P13-$Q13) -> 3541.6667 | S13: =IF($B13="","",IF(COUNTIFS($A$4:$A$2003,$A13-1,$B$4:$B$2003,$B13)=0,"first day",IF(SUMIFS($M$4:$M$2003,$A$4:$A$2003,$A13-1,$B$4:$B$2003,$B13)=$J13,"OK","CHECK"))) -> first day | T13: =IF($B13="","",IFERROR(INDEX(Drinks!$D$4:$D$53,MATCH($B13,Drinks!$A$4:$A$53,0)),0)) -> 791.66667
A14: 46256 | B14: Booster Gin | C14: 0 | D14: 0 | E14: 0 | F14: =IF($B14="","",$C14+$D14-$E14) -> 0 | G14: =IF($B14="","",IFERROR(INDEX(Drinks!$C$4:$C$53,MATCH($B14,Drinks!$A$4:$A$53,0)),0)) -> 8500 | H14: =IF($B14="","",$D14*$G14) -> 0 | I14: =IF($B14="","",$F14*$G14) -> 0 | J14: 5 | K14: =IF($B14="","",$E14*IFERROR(INDEX(Drinks!$B$4:$B$53,MATCH($B14,Drinks!$A$4:$A$53,0)),0)) -> 0 | L14: =IF($B14="","",$J14+$K14) -> 5 | M14: 0 | N14: =IF($B14="","",$L14-$M14) -> 5 | O14: =IF($B14="","",IFERROR(INDEX(Drinks!$E$4:$E$53,MATCH($B14,Drinks!$A$4:$A$53,0)),0)) -> 1000 | P14: =IF($B14="","",$N14*$O14) -> 5000 | Q14: =IF($B14="","",$N14*IFERROR(INDEX(Drinks!$D$4:$D$53,MATCH($B14,Drinks!$A$4:$A$53,0)),0)) -> 3541.6667 | R14: =IF($B14="","",$P14-$Q14) -> 1458.3333 | S14: =IF($B14="","",IF(COUNTIFS($A$4:$A$2003,$A14-1,$B$4:$B$2003,$B14)=0,"first day",IF(SUMIFS($M$4:$M$2003,$A$4:$A$2003,$A14-1,$B$4:$B$2003,$B14)=$J14,"OK","CHECK"))) -> first day | T14: =IF($B14="","",IFERROR(INDEX(Drinks!$D$4:$D$53,MATCH($B14,Drinks!$A$4:$A$53,0)),0)) -> 708.33333
A15: 46256 | B15: Big Guinness | C15: 1 | D15: 0 | E15: 1 | F15: =IF($B15="","",$C15+$D15-$E15) -> 0 | G15: =IF($B15="","",IFERROR(INDEX(Drinks!$C$4:$C$53,MATCH($B15,Drinks!$A$4:$A$53,0)),0)) -> 14000 | H15: =IF($B15="","",$D15*$G15) -> 0 | I15: =IF($B15="","",$F15*$G15) -> 0 | J15: 12 | K15: =IF($B15="","",$E15*IFERROR(INDEX(Drinks!$B$4:$B$53,MATCH($B15,Drinks!$A$4:$A$53,0)),0)) -> 12 | L15: =IF($B15="","",$J15+$K15) -> 24 | M15: 11 | N15: =IF($B15="","",$L15-$M15) -> 13 | O15: =IF($B15="","",IFERROR(INDEX(Drinks!$E$4:$E$53,MATCH($B15,Drinks!$A$4:$A$53,0)),0)) -> 1500 | P15: =IF($B15="","",$N15*$O15) -> 19500 | Q15: =IF($B15="","",$N15*IFERROR(INDEX(Drinks!$D$4:$D$53,MATCH($B15,Drinks!$A$4:$A$53,0)),0)) -> 15166.667 | R15: =IF($B15="","",$P15-$Q15) -> 4333.3333 | S15: =IF($B15="","",IF(COUNTIFS($A$4:$A$2003,$A15-1,$B$4:$B$2003,$B15)=0,"first day",IF(SUMIFS($M$4:$M$2003,$A$4:$A$2003,$A15-1,$B$4:$B$2003,$B15)=$J15,"OK","CHECK"))) -> first day | T15: =IF($B15="","",IFERROR(INDEX(Drinks!$D$4:$D$53,MATCH($B15,Drinks!$A$4:$A$53,0)),0)) -> 1166.6667
A16: 46256 | B16: Small Guinness | C16: 2 | D16: 0 | E16: 0 | F16: =IF($B16="","",$C16+$D16-$E16) -> 2 | G16: =IF($B16="","",IFERROR(INDEX(Drinks!$C$4:$C$53,MATCH($B16,Drinks!$A$4:$A$53,0)),0)) -> 17000 | H16: =IF($B16="","",$D16*$G16) -> 0 | I16: =IF($B16="","",$F16*$G16) -> 34000 | J16: 64 | K16: =IF($B16="","",$E16*IFERROR(INDEX(Drinks!$B$4:$B$53,MATCH($B16,Drinks!$A$4:$A$53,0)),0)) -> 0 | L16: =IF($B16="","",$J16+$K16) -> 64 | M16: 24 | N16: =IF($B16="","",$L16-$M16) -> 40 | O16: =IF($B16="","",IFERROR(INDEX(Drinks!$E$4:$E$53,MATCH($B16,Drinks!$A$4:$A$53,0)),0)) -> 1000 | P16: =IF($B16="","",$N16*$O16) -> 40000 | Q16: =IF($B16="","",$N16*IFERROR(INDEX(Drinks!$D$4:$D$53,MATCH($B16,Drinks!$A$4:$A$53,0)),0)) -> 28333.333 | R16: =IF($B16="","",$P16-$Q16) -> 11666.667 | S16: =IF($B16="","",IF(COUNTIFS($A$4:$A$2003,$A16-1,$B$4:$B$2003,$B16)=0,"first day",IF(SUMIFS($M$4:$M$2003,$A$4:$A$2003,$A16-1,$B$4:$B$2003,$B16)=$J16,"OK","CHECK"))) -> first day | T16: =IF($B16="","",IFERROR(INDEX(Drinks!$D$4:$D$53,MATCH($B16,Drinks!$A$4:$A$53,0)),0)) -> 708.33333
... A27: 46256 | B27: Reaktor | C27: 0 | D27: 5 | E27: 3 | F27: =IF($B27="","",$C27+$D27-$E27) -> 2 | G27: =IF($B27="","",IFERROR(INDEX(Drinks!$C$4:$C$53,MATCH($B27,Drinks!$A$4:$A$53,0)),0)) -> 4300 | H27: =IF($B27="","",$D27*$G27) -> 21500 | I27: =IF($B27="","",$F27*$G27) -> 8600 | J27: 0 | K27: =IF($B27="","",$E27*IFERROR(INDEX(Drinks!$B$4:$B$53,MATCH($B27,Drinks!$A$4:$A$53,0)),0)) -> 36 | L27: =IF($B27="","",$J27+$K27) -> 36 | M27: 30 | N27: =IF($B27="","",$L27-$M27) -> 6 | O27: =IF($B27="","",IFERROR(INDEX(Drinks!$E$4:$E$53,MATCH($B27,Drinks!$A$4:$A$53,0)),0)) -> 500 | P27: =IF($B27="","",$N27*$O27) -> 3000 | Q27: =IF($B27="","",$N27*IFERROR(INDEX(Drinks!$D$4:$D$53,MATCH($B27,Drinks!$A$4:$A$53,0)),0)) -> 2150 | R27: =IF($B27="","",$P27-$Q27) -> 850 | S27: =IF($B27="","",IF(COUNTIFS($A$4:$A$2003,$A27-1,$B$4:$B$2003,$B27)=0,"first day",IF(SUMIFS($M$4:$M$2003,$A$4:$A$2003,$A27-1,$B$4:$B$2003,$B27)=$J27,"OK","CHECK"))) -> first day | T27: =IF($B27="","",IFERROR(INDEX(Drinks!$D$4:$D$53,MATCH($B27,Drinks!$A$4:$A$53,0)),0)) -> 358.33333
F28: =IF($B28="","",$C28+$D28-$E28) | G28: =IF($B28="","",IFERROR(INDEX(Drinks!$C$4:$C$53,MATCH($B28,Drinks!$A$4:$A$53,0)),0)) | H28: =IF($B28="","",$D28*$G28) | I28: =IF($B28="","",$F28*$G28) | K28: =IF($B28="","",$E28*IFERROR(INDEX(Drinks!$B$4:$B$53,MATCH($B28,Drinks!$A$4:$A$53,0)),0)) | L28: =IF($B28="","",$J28+$K28) | N28: =IF($B28="","",$L28-$M28) | O28: =IF($B28="","",IFERROR(INDEX(Drinks!$E$4:$E$53,MATCH($B28,Drinks!$A$4:$A$53,0)),0)) | P28: =IF($B28="","",$N28*$O28) | Q28: =IF($B28="","",$N28*IFERROR(INDEX(Drinks!$D$4:$D$53,MATCH($B28,Drinks!$A$4:$A$53,0)),0)) | R28: =IF($B28="","",$P28-$Q28) | S28: =IF($B28="","",IF(COUNTIFS($A$4:$A$2003,$A28-1,$B$4:$B$2003,$B28)=0,"first day",IF(SUMIFS($M$4:$M$2003,$A$4:$A$2003,$A28-1,$B$4:$B$2003,$B28)=$J28,"OK","CHECK"))) | T28: =IF($B28="","",IFERROR(INDEX(Drinks!$D$4:$D$53,MATCH($B28,Drinks!$A$4:$A$53,0)),0))
F29: =IF($B29="","",$C29+$D29-$E29) | G29: =IF($B29="","",IFERROR(INDEX(Drinks!$C$4:$C$53,MATCH($B29,Drinks!$A$4:$A$53,0)),0)) | H29: =IF($B29="","",$D29*$G29) | I29: =IF($B29="","",$F29*$G29) | K29: =IF($B29="","",$E29*IFERROR(INDEX(Drinks!$B$4:$B$53,MATCH($B29,Drinks!$A$4:$A$53,0)),0)) | L29: =IF($B29="","",$J29+$K29) | N29: =IF($B29="","",$L29-$M29) | O29: =IF($B29="","",IFERROR(INDEX(Drinks!$E$4:$E$53,MATCH($B29,Drinks!$A$4:$A$53,0)),0)) | P29: =IF($B29="","",$N29*$O29) | Q29: =IF($B29="","",$N29*IFERROR(INDEX(Drinks!$D$4:$D$53,MATCH($B29,Drinks!$A$4:$A$53,0)),0)) | R29: =IF($B29="","",$P29-$Q29) | S29: =IF($B29="","",IF(COUNTIFS($A$4:$A$2003,$A29-1,$B$4:$B$2003,$B29)=0,"first day",IF(SUMIFS($M$4:$M$2003,$A$4:$A$2003,$A29-1,$B$4:$B$2003,$B29)=$J29,"OK","CHECK"))) | T29: =IF($B29="","",IFERROR(INDEX(Drinks!$D$4:$D$53,MATCH($B29,Drinks!$A$4:$A$53,0)),0))
F30: =IF($B30="","",$C30+$D30-$E30) | G30: =IF($B30="","",IFERROR(INDEX(Drinks!$C$4:$C$53,MATCH($B30,Drinks!$A$4:$A$53,0)),0)) | H30: =IF($B30="","",$D30*$G30) | I30: =IF($B30="","",$F30*$G30) | K30: =IF($B30="","",$E30*IFERROR(INDEX(Drinks!$B$4:$B$53,MATCH($B30,Drinks!$A$4:$A$53,0)),0)) | L30: =IF($B30="","",$J30+$K30) | N30: =IF($B30="","",$L30-$M30) | O30: =IF($B30="","",IFERROR(INDEX(Drinks!$E$4:$E$53,MATCH($B30,Drinks!$A$4:$A$53,0)),0)) | P30: =IF($B30="","",$N30*$O30) | Q30: =IF($B30="","",$N30*IFERROR(INDEX(Drinks!$D$4:$D$53,MATCH($B30,Drinks!$A$4:$A$53,0)),0)) | R30: =IF($B30="","",$P30-$Q30) | S30: =IF($B30="","",IF(COUNTIFS($A$4:$A$2003,$A30-1,$B$4:$B$2003,$B30)=0,"first day",IF(SUMIFS($M$4:$M$2003,$A$4:$A$2003,$A30-1,$B$4:$B$2003,$B30)=$J30,"OK","CHECK"))) | T30: =IF($B30="","",IFERROR(INDEX(Drinks!$D$4:$D$53,MATCH($B30,Drinks!$A$4:$A$53,0)),0))
F31: =IF($B31="","",$C31+$D31-$E31) | G31: =IF($B31="","",IFERROR(INDEX(Drinks!$C$4:$C$53,MATCH($B31,Drinks!$A$4:$A$53,0)),0)) | H31: =IF($B31="","",$D31*$G31) | I31: =IF($B31="","",$F31*$G31) | K31: =IF($B31="","",$E31*IFERROR(INDEX(Drinks!$B$4:$B$53,MATCH($B31,Drinks!$A$4:$A$53,0)),0)) | L31: =IF($B31="","",$J31+$K31) | N31: =IF($B31="","",$L31-$M31) | O31: =IF($B31="","",IFERROR(INDEX(Drinks!$E$4:$E$53,MATCH($B31,Drinks!$A$4:$A$53,0)),0)) | P31: =IF($B31="","",$N31*$O31) | Q31: =IF($B31="","",$N31*IFERROR(INDEX(Drinks!$D$4:$D$53,MATCH($B31,Drinks!$A$4:$A$53,0)),0)) | R31: =IF($B31="","",$P31-$Q31) | S31: =IF($B31="","",IF(COUNTIFS($A$4:$A$2003,$A31-1,$B$4:$B$2003,$B31)=0,"first day",IF(SUMIFS($M$4:$M$2003,$A$4:$A$2003,$A31-1,$B$4:$B$2003,$B31)=$J31,"OK","CHECK"))) | T31: =IF($B31="","",IFERROR(INDEX(Drinks!$D$4:$D$53,MATCH($B31,Drinks!$A$4:$A$53,0)),0))
F32: =IF($B32="","",$C32+$D32-$E32) | G32: =IF($B32="","",IFERROR(INDEX(Drinks!$C$4:$C$53,MATCH($B32,Drinks!$A$4:$A$53,0)),0)) | H32: =IF($B32="","",$D32*$G32) | I32: =IF($B32="","",$F32*$G32) | K32: =IF($B32="","",$E32*IFERROR(INDEX(Drinks!$B$4:$B$53,MATCH($B32,Drinks!$A$4:$A$53,0)),0)) | L32: =IF($B32="","",$J32+$K32) | N32: =IF($B32="","",$L32-$M32) | O32: =IF($B32="","",IFERROR(INDEX(Drinks!$E$4:$E$53,MATCH($B32,Drinks!$A$4:$A$53,0)),0)) | P32: =IF($B32="","",$N32*$O32) | Q32: =IF($B32="","",$N32*IFERROR(INDEX(Drinks!$D$4:$D$53,MATCH($B32,Drinks!$A$4:$A$53,0)),0)) | R32: =IF($B32="","",$P32-$Q32) | S32: =IF($B32="","",IF(COUNTIFS($A$4:$A$2003,$A32-1,$B$4:$B$2003,$B32)=0,"first day",IF(SUMIFS($M$4:$M$2003,$A$4:$A$2003,$A32-1,$B$4:$B$2003,$B32)=$J32,"OK","CHECK"))) | T32: =IF($B32="","",IFERROR(INDEX(Drinks!$D$4:$D$53,MATCH($B32,Drinks!$A$4:$A$53,0)),0))
F33: =IF($B33="","",$C33+$D33-$E33) | G33: =IF($B33="","",IFERROR(INDEX(Drinks!$C$4:$C$53,MATCH($B33,Drinks!$A$4:$A$53,0)),0)) | H33: =IF($B33="","",$D33*$G33) | I33: =IF($B33="","",$F33*$G33) | K33: =IF($B33="","",$E33*IFERROR(INDEX(Drinks!$B$4:$B$53,MATCH($B33,Drinks!$A$4:$A$53,0)),0)) | L33: =IF($B33="","",$J33+$K33) | N33: =IF($B33="","",$L33-$M33) | O33: =IF($B33="","",IFERROR(INDEX(Drinks!$E$4:$E$53,MATCH($B33,Drinks!$A$4:$A$53,0)),0)) | P33: =IF($B33="","",$N33*$O33) | Q33: =IF($B33="","",$N33*IFERROR(INDEX(Drinks!$D$4:$D$53,MATCH($B33,Drinks!$A$4:$A$53,0)),0)) | R33: =IF($B33="","",$P33-$Q33) | S33: =IF($B33="","",IF(COUNTIFS($A$4:$A$2003,$A33-1,$B$4:$B$2003,$B33)=0,"first day",IF(SUMIFS($M$4:$M$2003,$A$4:$A$2003,$A33-1,$B$4:$B$2003,$B33)=$J33,"OK","CHECK"))) | T33: =IF($B33="","",IFERROR(INDEX(Drinks!$D$4:$D$53,MATCH($B33,Drinks!$A$4:$A$53,0)),0))
F34: =IF($B34="","",$C34+$D34-$E34) | G34: =IF($B34="","",IFERROR(INDEX(Drinks!$C$4:$C$53,MATCH($B34,Drinks!$A$4:$A$53,0)),0)) | H34: =IF($B34="","",$D34*$G34) | I34: =IF($B34="","",$F34*$G34) | K34: =IF($B34="","",$E34*IFERROR(INDEX(Drinks!$B$4:$B$53,MATCH($B34,Drinks!$A$4:$A$53,0)),0)) | L34: =IF($B34="","",$J34+$K34) | N34: =IF($B34="","",$L34-$M34) | O34: =IF($B34="","",IFERROR(INDEX(Drinks!$E$4:$E$53,MATCH($B34,Drinks!$A$4:$A$53,0)),0)) | P34: =IF($B34="","",$N34*$O34) | Q34: =IF($B34="","",$N34*IFERROR(INDEX(Drinks!$D$4:$D$53,MATCH($B34,Drinks!$A$4:$A$53,0)),0)) | R34: =IF($B34="","",$P34-$Q34) | S34: =IF($B34="","",IF(COUNTIFS($A$4:$A$2003,$A34-1,$B$4:$B$2003,$B34)=0,"first day",IF(SUMIFS($M$4:$M$2003,$A$4:$A$2003,$A34-1,$B$4:$B$2003,$B34)=$J34,"OK","CHECK"))) | T34: =IF($B34="","",IFERROR(INDEX(Drinks!$D$4:$D$53,MATCH($B34,Drinks!$A$4:$A$53,0)),0))
F35: =IF($B35="","",$C35+$D35-$E35) | G35: =IF($B35="","",IFERROR(INDEX(Drinks!$C$4:$C$53,MATCH($B35,Drinks!$A$4:$A$53,0)),0)) | H35: =IF($B35="","",$D35*$G35) | I35: =IF($B35="","",$F35*$G35) | K35: =IF($B35="","",$E35*IFERROR(INDEX(Drinks!$B$4:$B$53,MATCH($B35,Drinks!$A$4:$A$53,0)),0)) | L35: =IF($B35="","",$J35+$K35) | N35: =IF($B35="","",$L35-$M35) | O35: =IF($B35="","",IFERROR(INDEX(Drinks!$E$4:$E$53,MATCH($B35,Drinks!$A$4:$A$53,0)),0)) | P35: =IF($B35="","",$N35*$O35) | Q35: =IF($B35="","",$N35*IFERROR(INDEX(Drinks!$D$4:$D$53,MATCH($B35,Drinks!$A$4:$A$53,0)),0)) | R35: =IF($B35="","",$P35-$Q35) | S35: =IF($B35="","",IF(COUNTIFS($A$4:$A$2003,$A35-1,$B$4:$B$2003,$B35)=0,"first day",IF(SUMIFS($M$4:$M$2003,$A$4:$A$2003,$A35-1,$B$4:$B$2003,$B35)=$J35,"OK","CHECK"))) | T35: =IF($B35="","",IFERROR(INDEX(Drinks!$D$4:$D$53,MATCH($B35,Drinks!$A$4:$A$53,0)),0))
F36: =IF($B36="","",$C36+$D36-$E36) | G36: =IF($B36="","",IFERROR(INDEX(Drinks!$C$4:$C$53,MATCH($B36,Drinks!$A$4:$A$53,0)),0)) | H36: =IF($B36="","",$D36*$G36) | I36: =IF($B36="","",$F36*$G36) | K36: =IF($B36="","",$E36*IFERROR(INDEX(Drinks!$B$4:$B$53,MATCH($B36,Drinks!$A$4:$A$53,0)),0)) | L36: =IF($B36="","",$J36+$K36) | N36: =IF($B36="","",$L36-$M36) | O36: =IF($B36="","",IFERROR(INDEX(Drinks!$E$4:$E$53,MATCH($B36,Drinks!$A$4:$A$53,0)),0)) | P36: =IF($B36="","",$N36*$O36) | Q36: =IF($B36="","",$N36*IFERROR(INDEX(Drinks!$D$4:$D$53,MATCH($B36,Drinks!$A$4:$A$53,0)),0)) | R36: =IF($B36="","",$P36-$Q36) | S36: =IF($B36="","",IF(COUNTIFS($A$4:$A$2003,$A36-1,$B$4:$B$2003,$B36)=0,"first day",IF(SUMIFS($M$4:$M$2003,$A$4:$A$2003,$A36-1,$B$4:$B$2003,$B36)=$J36,"OK","CHECK"))) | T36: =IF($B36="","",IFERROR(INDEX(Drinks!$D$4:$D$53,MATCH($B36,Drinks!$A$4:$A$53,0)),0))
F37: =IF($B37="","",$C37+$D37-$E37) | G37: =IF($B37="","",IFERROR(INDEX(Drinks!$C$4:$C$53,MATCH($B37,Drinks!$A$4:$A$53,0)),0)) | H37: =IF($B37="","",$D37*$G37) | I37: =IF($B37="","",$F37*$G37) | K37: =IF($B37="","",$E37*IFERROR(INDEX(Drinks!$B$4:$B$53,MATCH($B37,Drinks!$A$4:$A$53,0)),0)) | L37: =IF($B37="","",$J37+$K37) | N37: =IF($B37="","",$L37-$M37) | O37: =IF($B37="","",IFERROR(INDEX(Drinks!$E$4:$E$53,MATCH($B37,Drinks!$A$4:$A$53,0)),0)) | P37: =IF($B37="","",$N37*$O37) | Q37: =IF($B37="","",$N37*IFERROR(INDEX(Drinks!$D$4:$D$53,MATCH($B37,Drinks!$A$4:$A$53,0)),0)) | R37: =IF($B37="","",$P37-$Q37) | S37: =IF($B37="","",IF(COUNTIFS($A$4:$A$2003,$A37-1,$B$4:$B$2003,$B37)=0,"first day",IF(SUMIFS($M$4:$M$2003,$A$4:$A$2003,$A37-1,$B$4:$B$2003,$B37)=$J37,"OK","CHECK"))) | T37: =IF($B37="","",IFERROR(INDEX(Drinks!$D$4:$D$53,MATCH($B37,Drinks!$A$4:$A$53,0)),0))
F38: =IF($B38="","",$C38+$D38-$E38) | G38: =IF($B38="","",IFERROR(INDEX(Drinks!$C$4:$C$53,MATCH($B38,Drinks!$A$4:$A$53,0)),0)) | H38: =IF($B38="","",$D38*$G38) | I38: =IF($B38="","",$F38*$G38) | K38: =IF($B38="","",$E38*IFERROR(INDEX(Drinks!$B$4:$B$53,MATCH($B38,Drinks!$A$4:$A$53,0)),0)) | L38: =IF($B38="","",$J38+$K38) | N38: =IF($B38="","",$L38-$M38) | O38: =IF($B38="","",IFERROR(INDEX(Drinks!$E$4:$E$53,MATCH($B38,Drinks!$A$4:$A$53,0)),0)) | P38: =IF($B38="","",$N38*$O38) | Q38: =IF($B38="","",$N38*IFERROR(INDEX(Drinks!$D$4:$D$53,MATCH($B38,Drinks!$A$4:$A$53,0)),0)) | R38: =IF($B38="","",$P38-$Q38) | S38: =IF($B38="","",IF(COUNTIFS($A$4:$A$2003,$A38-1,$B$4:$B$2003,$B38)=0,"first day",IF(SUMIFS($M$4:$M$2003,$A$4:$A$2003,$A38-1,$B$4:$B$2003,$B38)=$J38,"OK","CHECK"))) | T38: =IF($B38="","",IFERROR(INDEX(Drinks!$D$4:$D$53,MATCH($B38,Drinks!$A$4:$A$53,0)),0))
F39: =IF($B39="","",$C39+$D39-$E39) | G39: =IF($B39="","",IFERROR(INDEX(Drinks!$C$4:$C$53,MATCH($B39,Drinks!$A$4:$A$53,0)),0)) | H39: =IF($B39="","",$D39*$G39) | I39: =IF($B39="","",$F39*$G39) | K39: =IF($B39="","",$E39*IFERROR(INDEX(Drinks!$B$4:$B$53,MATCH($B39,Drinks!$A$4:$A$53,0)),0)) | L39: =IF($B39="","",$J39+$K39) | N39: =IF($B39="","",$L39-$M39) | O39: =IF($B39="","",IFERROR(INDEX(Drinks!$E$4:$E$53,MATCH($B39,Drinks!$A$4:$A$53,0)),0)) | P39: =IF($B39="","",$N39*$O39) | Q39: =IF($B39="","",$N39*IFERROR(INDEX(Drinks!$D$4:$D$53,MATCH($B39,Drinks!$A$4:$A$53,0)),0)) | R39: =IF($B39="","",$P39-$Q39) | S39: =IF($B39="","",IF(COUNTIFS($A$4:$A$2003,$A39-1,$B$4:$B$2003,$B39)=0,"first day",IF(SUMIFS($M$4:$M$2003,$A$4:$A$2003,$A39-1,$B$4:$B$2003,$B39)=$J39,"OK","CHECK"))) | T39: =IF($B39="","",IFERROR(INDEX(Drinks!$D$4:$D$53,MATCH($B39,Drinks!$A$4:$A$53,0)),0))
... F2003: =IF($B2003="","",$C2003+$D2003-$E2003) | G2003: =IF($B2003="","",IFERROR(INDEX(Drinks!$C$4:$C$53,MATCH($B2003,Drinks!$A$4:$A$53,0)),0)) | H2003: =IF($B2003="","",$D2003*$G2003) | I2003: =IF($B2003="","",$F2003*$G2003) | K2003: =IF($B2003="","",$E2003*IFERROR(INDEX(Drinks!$B$4:$B$53,MATCH($B2003,Drinks!$A$4:$A$53,0)),0)) | L2003: =IF($B2003="","",$J2003+$K2003) | N2003: =IF($B2003="","",$L2003-$M2003) | O2003: =IF($B2003="","",IFERROR(INDEX(Drinks!$E$4:$E$53,MATCH($B2003,Drinks!$A$4:$A$53,0)),0)) | P2003: =IF($B2003="","",$N2003*$O2003) | Q2003: =IF($B2003="","",$N2003*IFERROR(INDEX(Drinks!$D$4:$D$53,MATCH($B2003,Drinks!$A$4:$A$53,0)),0)) | R2003: =IF($B2003="","",$P2003-$Q2003) | S2003: =IF($B2003="","",IF(COUNTIFS($A$4:$A$2003,$A2003-1,$B$4:$B$2003,$B2003)=0,"first day",IF(SUMIFS($M$4:$M$2003,$A$4:$A$2003,$A2003-1,$B$4:$B$2003,$B2003)=$J2003,"OK","CHECK"))) | T2003: =IF($B2003="","",IFERROR(INDEX(Drinks!$D$4:$D$53,MATCH($B2003,Drinks!$A$4:$A$53,0)),0))

Sheet Daily Cash
A1: CONTROL SHEET OF BUSINESS TREND — one row per day
A2: Sales, cost and profit come from Daily Entry. You only type the date and the deductions.
A3: Date | B3: Sales | C3: Recovered | D3: Damaged | E3: Expenses | F3: Expense Description | G3: Shortage | H3: Debt | I3: Debt Description | J3: BALANCE SALES (cash to bank) | K3: Cost of Sales | L3: Gross Profit | M3: NET PROFIT | N3: Stock Purchased | O3: Warehouse Value | P3: Bar Stock Value
A4: 46256 | B4: =IF($A4="","",SUMIFS('Daily Entry'!$P$4:$P$2003,'Daily Entry'!$A$4:$A$2003,$A4)) -> 272500 | E4: 500 | F4: Photocopy | H4: 11000 | I4: Staff | J4: =IF($A4="","",$B4+$C4-$D4-$E4-$G4-$H4) -> 261000 | K4: =IF($A4="","",SUMIFS('Daily Entry'!$Q$4:$Q$2003,'Daily Entry'!$A$4:$A$2003,$A4)) -> 196216.67 | L4: =IF($A4="","",$B4-$K4) -> 76283.333 | M4: =IF($A4="","",$L4-$D4-$E4-$G4) -> 75783.333 | N4: =IF($A4="","",SUMIFS('Daily Entry'!$H$4:$H$2003,'Daily Entry'!$A$4:$A$2003,$A4)) -> 210500 | O4: =IF($A4="","",SUMIFS('Daily Entry'!$I$4:$I$2003,'Daily Entry'!$A$4:$A$2003,$A4)) -> 189200 | P4: =IF($A4="","",SUMPRODUCT(('Daily Entry'!$A$4:$A$2003=$A4)*('Daily Entry'!$M$4:$M$2003)*('Daily Entry'!$D$4:$D$2003))) -> 1240
B5: =IF($A5="","",SUMIFS('Daily Entry'!$P$4:$P$2003,'Daily Entry'!$A$4:$A$2003,$A5)) | J5: =IF($A5="","",$B5+$C5-$D5-$E5-$G5-$H5) | K5: =IF($A5="","",SUMIFS('Daily Entry'!$Q$4:$Q$2003,'Daily Entry'!$A$4:$A$2003,$A5)) | L5: =IF($A5="","",$B5-$K5) | M5: =IF($A5="","",$L5-$D5-$E5-$G5) | N5: =IF($A5="","",SUMIFS('Daily Entry'!$H$4:$H$2003,'Daily Entry'!$A$4:$A$2003,$A5)) | O5: =IF($A5="","",SUMIFS('Daily Entry'!$I$4:$I$2003,'Daily Entry'!$A$4:$A$2003,$A5)) | P5: =IF($A5="","",SUMPRODUCT(('Daily Entry'!$A$4:$A$2003=$A5)*('Daily Entry'!$M$4:$M$2003)*('Daily Entry'!$D$4:$D$2003)))
B6: =IF($A6="","",SUMIFS('Daily Entry'!$P$4:$P$2003,'Daily Entry'!$A$4:$A$2003,$A6)) | J6: =IF($A6="","",$B6+$C6-$D6-$E6-$G6-$H6) | K6: =IF($A6="","",SUMIFS('Daily Entry'!$Q$4:$Q$2003,'Daily Entry'!$A$4:$A$2003,$A6)) | L6: =IF($A6="","",$B6-$K6) | M6: =IF($A6="","",$L6-$D6-$E6-$G6) | N6: =IF($A6="","",SUMIFS('Daily Entry'!$H$4:$H$2003,'Daily Entry'!$A$4:$A$2003,$A6)) | O6: =IF($A6="","",SUMIFS('Daily Entry'!$I$4:$I$2003,'Daily Entry'!$A$4:$A$2003,$A6)) | P6: =IF($A6="","",SUMPRODUCT(('Daily Entry'!$A$4:$A$2003=$A6)*('Daily Entry'!$M$4:$M$2003)*('Daily Entry'!$D$4:$D$2003)))
B7: =IF($A7="","",SUMIFS('Daily Entry'!$P$4:$P$2003,'Daily Entry'!$A$4:$A$2003,$A7)) | J7: =IF($A7="","",$B7+$C7-$D7-$E7-$G7-$H7) | K7: =IF($A7="","",SUMIFS('Daily Entry'!$Q$4:$Q$2003,'Daily Entry'!$A$4:$A$2003,$A7)) | L7: =IF($A7="","",$B7-$K7) | M7: =IF($A7="","",$L7-$D7-$E7-$G7) | N7: =IF($A7="","",SUMIFS('Daily Entry'!$H$4:$H$2003,'Daily Entry'!$A$4:$A$2003,$A7)) | O7: =IF($A7="","",SUMIFS('Daily Entry'!$I$4:$I$2003,'Daily Entry'!$A$4:$A$2003,$A7)) | P7: =IF($A7="","",SUMPRODUCT(('Daily Entry'!$A$4:$A$2003=$A7)*('Daily Entry'!$M$4:$M$2003)*('Daily Entry'!$D$4:$D$2003)))
B8: =IF($A8="","",SUMIFS('Daily Entry'!$P$4:$P$2003,'Daily Entry'!$A$4:$A$2003,$A8)) | J8: =IF($A8="","",$B8+$C8-$D8-$E8-$G8-$H8) | K8: =IF($A8="","",SUMIFS('Daily Entry'!$Q$4:$Q$2003,'Daily Entry'!$A$4:$A$2003,$A8)) | L8: =IF($A8="","",$B8-$K8) | M8: =IF($A8="","",$L8-$D8-$E8-$G8) | N8: =IF($A8="","",SUMIFS('Daily Entry'!$H$4:$H$2003,'Daily Entry'!$A$4:$A$2003,$A8)) | O8: =IF($A8="","",SUMIFS('Daily Entry'!$I$4:$I$2003,'Daily Entry'!$A$4:$A$2003,$A8)) | P8: =IF($A8="","",SUMPRODUCT(('Daily Entry'!$A$4:$A$2003=$A8)*('Daily Entry'!$M$4:$M$2003)*('Daily Entry'!$D$4:$D$2003)))
B9: =IF($A9="","",SUMIFS('Daily Entry'!$P$4:$P$2003,'Daily Entry'!$A$4:$A$2003,$A9)) | J9: =IF($A9="","",$B9+$C9-$D9-$E9-$G9-$H9) | K9: =IF($A9="","",SUMIFS('Daily Entry'!$Q$4:$Q$2003,'Daily Entry'!$A$4:$A$2003,$A9)) | L9: =IF($A9="","",$B9-$K9) | M9: =IF($A9="","",$L9-$D9-$E9-$G9) | N9: =IF($A9="","",SUMIFS('Daily Entry'!$H$4:$H$2003,'Daily Entry'!$A$4:$A$2003,$A9)) | O9: =IF($A9="","",SUMIFS('Daily Entry'!$I$4:$I$2003,'Daily Entry'!$A$4:$A$2003,$A9)) | P9: =IF($A9="","",SUMPRODUCT(('Daily Entry'!$A$4:$A$2003=$A9)*('Daily Entry'!$M$4:$M$2003)*('Daily Entry'!$D$4:$D$2003)))
B10: =IF($A10="","",SUMIFS('Daily Entry'!$P$4:$P$2003,'Daily Entry'!$A$4:$A$2003,$A10)) | J10: =IF($A10="","",$B10+$C10-$D10-$E10-$G10-$H10) | K10: =IF($A10="","",SUMIFS('Daily Entry'!$Q$4:$Q$2003,'Daily Entry'!$A$4:$A$2003,$A10)) | L10: =IF($A10="","",$B10-$K10) | M10: =IF($A10="","",$L10-$D10-$E10-$G10) | N10: =IF($A10="","",SUMIFS('Daily Entry'!$H$4:$H$2003,'Daily Entry'!$A$4:$A$2003,$A10)) | O10: =IF($A10="","",SUMIFS('Daily Entry'!$I$4:$I$2003,'Daily Entry'!$A$4:$A$2003,$A10)) | P10: =IF($A10="","",SUMPRODUCT(('Daily Entry'!$A$4:$A$2003=$A10)*('Daily Entry'!$M$4:$M$2003)*('Daily Entry'!$D$4:$D$2003)))
B11: =IF($A11="","",SUMIFS('Daily Entry'!$P$4:$P$2003,'Daily Entry'!$A$4:$A$2003,$A11)) | J11: =IF($A11="","",$B11+$C11-$D11-$E11-$G11-$H11) | K11: =IF($A11="","",SUMIFS('Daily Entry'!$Q$4:$Q$2003,'Daily Entry'!$A$4:$A$2003,$A11)) | L11: =IF($A11="","",$B11-$K11) | M11: =IF($A11="","",$L11-$D11-$E11-$G11) | N11: =IF($A11="","",SUMIFS('Daily Entry'!$H$4:$H$2003,'Daily Entry'!$A$4:$A$2003,$A11)) | O11: =IF($A11="","",SUMIFS('Daily Entry'!$I$4:$I$2003,'Daily Entry'!$A$4:$A$2003,$A11)) | P11: =IF($A11="","",SUMPRODUCT(('Daily Entry'!$A$4:$A$2003=$A11)*('Daily Entry'!$M$4:$M$2003)*('Daily Entry'!$D$4:$D$2003)))
B12: =IF($A12="","",SUMIFS('Daily Entry'!$P$4:$P$2003,'Daily Entry'!$A$4:$A$2003,$A12)) | J12: =IF($A12="","",$B12+$C12-$D12-$E12-$G12-$H12) | K12: =IF($A12="","",SUMIFS('Daily Entry'!$Q$4:$Q$2003,'Daily Entry'!$A$4:$A$2003,$A12)) | L12: =IF($A12="","",$B12-$K12) | M12: =IF($A12="","",$L12-$D12-$E12-$G12) | N12: =IF($A12="","",SUMIFS('Daily Entry'!$H$4:$H$2003,'Daily Entry'!$A$4:$A$2003,$A12)) | O12: =IF($A12="","",SUMIFS('Daily Entry'!$I$4:$I$2003,'Daily Entry'!$A$4:$A$2003,$A12)) | P12: =IF($A12="","",SUMPRODUCT(('Daily Entry'!$A$4:$A$2003=$A12)*('Daily Entry'!$M$4:$M$2003)*('Daily Entry'!$D$4:$D$2003)))
B13: =IF($A13="","",SUMIFS('Daily Entry'!$P$4:$P$2003,'Daily Entry'!$A$4:$A$2003,$A13)) | J13: =IF($A13="","",$B13+$C13-$D13-$E13-$G13-$H13) | K13: =IF($A13="","",SUMIFS('Daily Entry'!$Q$4:$Q$2003,'Daily Entry'!$A$4:$A$2003,$A13)) | L13: =IF($A13="","",$B13-$K13) | M13: =IF($A13="","",$L13-$D13-$E13-$G13) | N13: =IF($A13="","",SUMIFS('Daily Entry'!$H$4:$H$2003,'Daily Entry'!$A$4:$A$2003,$A13)) | O13: =IF($A13="","",SUMIFS('Daily Entry'!$I$4:$I$2003,'Daily Entry'!$A$4:$A$2003,$A13)) | P13: =IF($A13="","",SUMPRODUCT(('Daily Entry'!$A$4:$A$2003=$A13)*('Daily Entry'!$M$4:$M$2003)*('Daily Entry'!$D$4:$D$2003)))
B14: =IF($A14="","",SUMIFS('Daily Entry'!$P$4:$P$2003,'Daily Entry'!$A$4:$A$2003,$A14)) | J14: =IF($A14="","",$B14+$C14-$D14-$E14-$G14-$H14) | K14: =IF($A14="","",SUMIFS('Daily Entry'!$Q$4:$Q$2003,'Daily Entry'!$A$4:$A$2003,$A14)) | L14: =IF($A14="","",$B14-$K14) | M14: =IF($A14="","",$L14-$D14-$E14-$G14) | N14: =IF($A14="","",SUMIFS('Daily Entry'!$H$4:$H$2003,'Daily Entry'!$A$4:$A$2003,$A14)) | O14: =IF($A14="","",SUMIFS('Daily Entry'!$I$4:$I$2003,'Daily Entry'!$A$4:$A$2003,$A14)) | P14: =IF($A14="","",SUMPRODUCT(('Daily Entry'!$A$4:$A$2003=$A14)*('Daily Entry'!$M$4:$M$2003)*('Daily Entry'!$D$4:$D$2003)))
B15: =IF($A15="","",SUMIFS('Daily Entry'!$P$4:$P$2003,'Daily Entry'!$A$4:$A$2003,$A15)) | J15: =IF($A15="","",$B15+$C15-$D15-$E15-$G15-$H15) | K15: =IF($A15="","",SUMIFS('Daily Entry'!$Q$4:$Q$2003,'Daily Entry'!$A$4:$A$2003,$A15)) | L15: =IF($A15="","",$B15-$K15) | M15: =IF($A15="","",$L15-$D15-$E15-$G15) | N15: =IF($A15="","",SUMIFS('Daily Entry'!$H$4:$H$2003,'Daily Entry'!$A$4:$A$2003,$A15)) | O15: =IF($A15="","",SUMIFS('Daily Entry'!$I$4:$I$2003,'Daily Entry'!$A$4:$A$2003,$A15)) | P15: =IF($A15="","",SUMPRODUCT(('Daily Entry'!$A$4:$A$2003=$A15)*('Daily Entry'!$M$4:$M$2003)*('Daily Entry'!$D$4:$D$2003)))
B16: =IF($A16="","",SUMIFS('Daily Entry'!$P$4:$P$2003,'Daily Entry'!$A$4:$A$2003,$A16)) | J16: =IF($A16="","",$B16+$C16-$D16-$E16-$G16-$H16) | K16: =IF($A16="","",SUMIFS('Daily Entry'!$Q$4:$Q$2003,'Daily Entry'!$A$4:$A$2003,$A16)) | L16: =IF($A16="","",$B16-$K16) | M16: =IF($A16="","",$L16-$D16-$E16-$G16) | N16: =IF($A16="","",SUMIFS('Daily Entry'!$H$4:$H$2003,'Daily Entry'!$A$4:$A$2003,$A16)) | O16: =IF($A16="","",SUMIFS('Daily Entry'!$I$4:$I$2003,'Daily Entry'!$A$4:$A$2003,$A16)) | P16: =IF($A16="","",SUMPRODUCT(('Daily Entry'!$A$4:$A$2003=$A16)*('Daily Entry'!$M$4:$M$2003)*('Daily Entry'!$D$4:$D$2003)))
... B403: =IF($A403="","",SUMIFS('Daily Entry'!$P$4:$P$2003,'Daily Entry'!$A$4:$A$2003,$A403)) | J403: =IF($A403="","",$B403+$C403-$D403-$E403-$G403-$H403) | K403: =IF($A403="","",SUMIFS('Daily Entry'!$Q$4:$Q$2003,'Daily Entry'!$A$4:$A$2003,$A403)) | L403: =IF($A403="","",$B403-$K403) | M403: =IF($A403="","",$L403-$D403-$E403-$G403) | N403: =IF($A403="","",SUMIFS('Daily Entry'!$H$4:$H$2003,'Daily Entry'!$A$4:$A$2003,$A403)) | O403: =IF($A403="","",SUMIFS('Daily Entry'!$I$4:$I$2003,'Daily Entry'!$A$4:$A$2003,$A403)) | P403: =IF($A403="","",SUMPRODUCT(('Daily Entry'!$A$4:$A$2003=$A403)*('Daily Entry'!$M$4:$M$2003)*('Daily Entry'!$D$4:$D$2003)))

Sheet Control Report
A1: CONTROL REPORT FOR: | D1: 46256 | G1: <- change this date and the whole report re-fills
B3: STOCK AT WAREHOUSE | H3: OPENING STOCK AT SNACK | J3: TOTAL STOCK AT SNACK | L3: CLOSING | M3: SALES
A4: Drinks | B4: Opening Crates/Pallet | C4: Purchase | D4: Closing Crates/Pallet | E4: Stock Sent to Snack | F4: Buying Price | G4: Amount | H4: Qty | I4: Supply | J4: Qty | K4: Closed | L4: Amt | M4: Qty | N4: Amt | O4: Gross Profit
A5: =IF(Drinks!$A4="","",Drinks!$A4) -> Doppel | B5: =IF($A5="","",IF(COUNTIFS('Daily Entry'!$A$4:$A$2003,$D$1,'Daily Entry'!$B$4:$B$2003,$A5)=0,"-",SUMIFS('Daily Entry'!$C$4:$C$2003,'Daily Entry'!$A$4:$A$2003,$D$1,'Daily Entry'!$B$4:$B$2003,$A5))) -> 0 | C5: =IF($A5="","",IF(COUNTIFS('Daily Entry'!$A$4:$A$2003,$D$1,'Daily Entry'!$B$4:$B$2003,$A5)=0,"-",SUMIFS('Daily Entry'!$D$4:$D$2003,'Daily Entry'!$A$4:$A$2003,$D$1,'Daily Entry'!$B$4:$B$2003,$A5))) -> 0 | D5: =IF($A5="","",IF(COUNTIFS('Daily Entry'!$A$4:$A$2003,$D$1,'Daily Entry'!$B$4:$B$2003,$A5)=0,"-",SUMIFS('Daily Entry'!$F$4:$F$2003,'Daily Entry'!$A$4:$A$2003,$D$1,'Daily Entry'!$B$4:$B$2003,$A5))) -> 0 | E5: =IF($A5="","",IF(COUNTIFS('Daily Entry'!$A$4:$A$2003,$D$1,'Daily Entry'!$B$4:$B$2003,$A5)=0,"-",SUMIFS('Daily Entry'!$E$4:$E$2003,'Daily Entry'!$A$4:$A$2003,$D$1,'Daily Entry'!$B$4:$B$2003,$A5))) -> 0 | F5: =IF($A5="","",IF(COUNTIFS('Daily Entry'!$A$4:$A$2003,$D$1,'Daily Entry'!$B$4:$B$2003,$A5)=0,"-",SUMIFS('Daily Entry'!$G$4:$G$2003,'Daily Entry'!$A$4:$A$2003,$D$1,'Daily Entry'!$B$4:$B$2003,$A5))) -> 8500 | G5: =IF($A5="","",IF(COUNTIFS('Daily Entry'!$A$4:$A$2003,$D$1,'Daily Entry'!$B$4:$B$2003,$A5)=0,"-",SUMIFS('Daily Entry'!$I$4:$I$2003,'Daily Entry'!$A$4:$A$2003,$D$1,'Daily Entry'!$B$4:$B$2003,$A5))) -> 0 | H5: =IF($A5="","",IF(COUNTIFS('Daily Entry'!$A$4:$A$2003,$D$1,'Daily Entry'!$B$4:$B$2003,$A5)=0,"-",SUMIFS('Daily Entry'!$J$4:$J$2003,'Daily Entry'!$A$4:$A$2003,$D$1,'Daily Entry'!$B$4:$B$2003,$A5))) -> 7 | I5: =IF($A5="","",IF(COUNTIFS('Daily Entry'!$A$4:$A$2003,$D$1,'Daily Entry'!$B$4:$B$2003,$A5)=0,"-",SUMIFS('Daily Entry'!$K$4:$K$2003,'Daily Entry'!$A$4:$A$2003,$D$1,'Daily Entry'!$B$4:$B$2003,$A5))) -> 0 | J5: =IF($A5="","",IF(COUNTIFS('Daily Entry'!$A$4:$A$2003,$D$1,'Daily Entry'!$B$4:$B$2003,$A5)=0,"-",SUMIFS('Daily Entry'!$L$4:$L$2003,'Daily Entry'!$A$4:$A$2003,$D$1,'Daily Entry'!$B$4:$B$2003,$A5))) -> 7 | K5: =IF($A5="","",IF(COUNTIFS('Daily Entry'!$A$4:$A$2003,$D$1,'Daily Entry'!$B$4:$B$2003,$A5)=0,"-",SUMIFS('Daily Entry'!$M$4:$M$2003,'Daily Entry'!$A$4:$A$2003,$D$1,'Daily Entry'!$B$4:$B$2003,$A5))) -> 1 | L5: =IF($A5="","",IF(COUNTIFS('Daily Entry'!$A$4:$A$2003,$D$1,'Daily Entry'!$B$4:$B$2003,$A5)=0,"-",SUMIFS('Daily Entry'!$O$4:$O$2003,'Daily Entry'!$A$4:$A$2003,$D$1,'Daily Entry'!$B$4:$B$2003,$A5))) -> 1000 | M5: =IF($A5="","",IF(COUNTIFS('Daily Entry'!$A$4:$A$2003,$D$1,'Daily Entry'!$B$4:$B$2003,$A5)=0,"-",SUMIFS('Daily Entry'!$N$4:$N$2003,'Daily Entry'!$A$4:$A$2003,$D$1,'Daily Entry'!$B$4:$B$2003,$A5))) -> 6 | N5: =IF($A5="","",IF(COUNTIFS('Daily Entry'!$A$4:$A$2003,$D$1,'Daily Entry'!$B$4:$B$2003,$A5)=0,"-",SUMIFS('Daily Entry'!$P$4:$P$2003,'Daily Entry'!$A$4:$A$2003,$D$1,'Daily Entry'!$B$4:$B$2003,$A5))) -> 6000 | O5: =IF($A5="","",IF(COUNTIFS('Daily Entry'!$A$4:$A$2003,$D$1,'Daily Entry'!$B$4:$B$2003,$A5)=0,"-",SUMIFS('Daily Entry'!$R$4:$R$2003,'Daily Entry'!$A$4:$A$2003,$D$1,'Daily Entry'!$B$4:$B$2003,$A5))) -> 1750
A6: =IF(Drinks!$A5="","",Drinks!$A5) -> Mutzig | B6: =IF($A6="","",IF(COUNTIFS('Daily Entry'!$A$4:$A$2003,$D$1,'Daily Entry'!$B$4:$B$2003,$A6)=0,"-",SUMIFS('Daily Entry'!$C$4:$C$2003,'Daily Entry'!$A$4:$A$2003,$D$1,'Daily Entry'!$B$4:$B$2003,$A6))) -> 0 | C6: =IF($A6="","",IF(COUNTIFS('Daily Entry'!$A$4:$A$2003,$D$1,'Daily Entry'!$B$4:$B$2003,$A6)=0,"-",SUMIFS('Daily Entry'!$D$4:$D$2003,'Daily Entry'!$A$4:$A$2003,$D$1,'Daily Entry'!$B$4:$B$2003,$A6))) -> 6 | D6: =IF($A6="","",IF(COUNTIFS('Daily Entry'!$A$4:$A$2003,$D$1,'Daily Entry'!$B$4:$B$2003,$A6)=0,"-",SUMIFS('Daily Entry'!$F$4:$F$2003,'Daily Entry'!$A$4:$A$2003,$D$1,'Daily Entry'!$B$4:$B$2003,$A6))) -> 0 | E6: =IF($A6="","",IF(COUNTIFS('Daily Entry'!$A$4:$A$2003,$D$1,'Daily Entry'!$B$4:$B$2003,$A6)=0,"-",SUMIFS('Daily Entry'!$E$4:$E$2003,'Daily Entry'!$A$4:$A$2003,$D$1,'Daily Entry'!$B$4:$B$2003,$A6))) -> 6 | F6: =IF($A6="","",IF(COUNTIFS('Daily Entry'!$A$4:$A$2003,$D$1,'Daily Entry'!$B$4:$B$2003,$A6)=0,"-",SUMIFS('Daily Entry'!$G$4:$G$2003,'Daily Entry'!$A$4:$A$2003,$D$1,'Daily Entry'!$B$4:$B$2003,$A6))) -> 8500 | G6: =IF($A6="","",IF(COUNTIFS('Daily Entry'!$A$4:$A$2003,$D$1,'Daily Entry'!$B$4:$B$2003,$A6)=0,"-",SUMIFS('Daily Entry'!$I$4:$I$2003,'Daily Entry'!$A$4:$A$2003,$D$1,'Daily Entry'!$B$4:$B$2003,$A6))) -> 0 | H6: =IF($A6="","",IF(COUNTIFS('Daily Entry'!$A$4:$A$2003,$D$1,'Daily Entry'!$B$4:$B$2003,$A6)=0,"-",SUMIFS('Daily Entry'!$J$4:$J$2003,'Daily Entry'!$A$4:$A$2003,$D$1,'Daily Entry'!$B$4:$B$2003,$A6))) -> 16 | I6: =IF($A6="","",IF(COUNTIFS('Daily Entry'!$A$4:$A$2003,$D$1,'Daily Entry'!$B$4:$B$2003,$A6)=0,"-",SUMIFS('Daily Entry'!$K$4:$K$2003,'Daily Entry'!$A$4:$A$2003,$D$1,'Daily Entry'!$B$4:$B$2003,$A6))) -> 72 | J6: =IF($A6="","",IF(COUNTIFS('Daily Entry'!$A$4:$A$2003,$D$1,'Daily Entry'!$B$4:$B$2003,$A6)=0,"-",SUMIFS('Daily Entry'!$L$4:$L$2003,'Daily Entry'!$A$4:$A$2003,$D$1,'Daily Entry'!$B$4:$B$2003,$A6))) -> 88 | K6: =IF($A6="","",IF(COUNTIFS('Daily Entry'!$A$4:$A$2003,$D$1,'Daily Entry'!$B$4:$B$2003,$A6)=0,"-",SUMIFS('Daily Entry'!$M$4:$M$2003,'Daily Entry'!$A$4:$A$2003,$D$1,'Daily Entry'!$B$4:$B$2003,$A6))) -> 73 | L6: =IF($A6="","",IF(COUNTIFS('Daily Entry'!$A$4:$A$2003,$D$1,'Daily Entry'!$B$4:$B$2003,$A6)=0,"-",SUMIFS('Daily Entry'!$O$4:$O$2003,'Daily Entry'!$A$4:$A$2003,$D$1,'Daily Entry'!$B$4:$B$2003,$A6))) -> 1000 | M6: =IF($A6="","",IF(COUNTIFS('Daily Entry'!$A$4:$A$2003,$D$1,'Daily Entry'!$B$4:$B$2003,$A6)=0,"-",SUMIFS('Daily Entry'!$N$4:$N$2003,'Daily Entry'!$A$4:$A$2003,$D$1,'Daily Entry'!$B$4:$B$2003,$A6))) -> 15 | N6: =IF($A6="","",IF(COUNTIFS('Daily Entry'!$A$4:$A$2003,$D$1,'Daily Entry'!$B$4:$B$2003,$A6)=0,"-",SUMIFS('Daily Entry'!$P$4:$P$2003,'Daily Entry'!$A$4:$A$2003,$D$1,'Daily Entry'!$B$4:$B$2003,$A6))) -> 15000 | O6: =IF($A6="","",IF(COUNTIFS('Daily Entry'!$A$4:$A$2003,$D$1,'Daily Entry'!$B$4:$B$2003,$A6)=0,"-",SUMIFS('Daily Entry'!$R$4:$R$2003,'Daily Entry'!$A$4:$A$2003,$D$1,'Daily Entry'!$B$4:$B$2003,$A6))) -> 4375
A7: =IF(Drinks!$A6="","",Drinks!$A6) -> Export | B7: =IF($A7="","",IF(COUNTIFS('Daily Entry'!$A$4:$A$2003,$D$1,'Daily Entry'!$B$4:$B$2003,$A7)=0,"-",SUMIFS('Daily Entry'!$C$4:$C$2003,'Daily Entry'!$A$4:$A$2003,$D$1,'Daily Entry'!$B$4:$B$2003,$A7))) -> 5 | C7: =IF($A7="","",IF(COUNTIFS('Daily Entry'!$A$4:$A$2003,$D$1,'Daily Entry'!$B$4:$B$2003,$A7)=0,"-",SUMIFS('Daily Entry'!$D$4:$D$2003,'Daily Entry'!$A$4:$A$2003,$D$1,'Daily Entry'!$B$4:$B$2003,$A7))) -> 0 | D7: =IF($A7="","",IF(COUNTIFS('Daily Entry'!$A$4:$A$2003,$D$1,'Daily Entry'!$B$4:$B$2003,$A7)=0,"-",SUMIFS('Daily Entry'!$F$4:$F$2003,'Daily Entry'!$A$4:$A$2003,$D$1,'Daily Entry'!$B$4:$B$2003,$A7))) -> 0 | E7: =IF($A7="","",IF(COUNTIFS('Daily Entry'!$A$4:$A$2003,$D$1,'Daily Entry'!$B$4:$B$2003,$A7)=0,"-",SUMIFS('Daily Entry'!$E$4:$E$2003,'Daily Entry'!$A$4:$A$2003,$D$1,'Daily Entry'!$B$4:$B$2003,$A7))) -> 5 | F7: =IF($A7="","",IF(COUNTIFS('Daily Entry'!$A$4:$A$2003,$D$1,'Daily Entry'!$B$4:$B$2003,$A7)=0,"-",SUMIFS('Daily Entry'!$G$4:$G$2003,'Daily Entry'!$A$4:$A$2003,$D$1,'Daily Entry'!$B$4:$B$2003,$A7))) -> 8500 | G7: =IF($A7="","",IF(COUNTIFS('Daily Entry'!$A$4:$A$2003,$D$1,'Daily Entry'!$B$4:$B$2003,$A7)=0,"-",SUMIFS('Daily Entry'!$I$4:$I$2003,'Daily Entry'!$A$4:$A$2003,$D$1,'Daily Entry'!$B$4:$B$2003,$A7))) -> 0 | H7: =IF($A7="","",IF(COUNTIFS('Daily Entry'!$A$4:$A$2003,$D$1,'Daily Entry'!$B$4:$B$2003,$A7)=0,"-",SUMIFS('Daily Entry'!$J$4:$J$2003,'Daily Entry'!$A$4:$A$2003,$D$1,'Daily Entry'!$B$4:$B$2003,$A7))) -> 27 | I7: =IF($A7="","",IF(COUNTIFS('Daily Entry'!$A$4:$A$2003,$D$1,'Daily Entry'!$B$4:$B$2003,$A7)=0,"-",SUMIFS('Daily Entry'!$K$4:$K$2003,'Daily Entry'!$A$4:$A$2003,$D$1,'Daily Entry'!$B$4:$B$2003,$A7))) -> 60 | J7: =IF($A7="","",IF(COUNTIFS('Daily Entry'!$A$4:$A$2003,$D$1,'Daily Entry'!$B$4:$B$2003,$A7)=0,"-",SUMIFS('Daily Entry'!$L$4:$L$2003,'Daily Entry'!$A$4:$A$2003,$D$1,'Daily Entry'!$B$4:$B$2003,$A7))) -> 87 | K7: =IF($A7="","",IF(COUNTIFS('Daily Entry'!$A$4:$A$2003,$D$1,'Daily Entry'!$B$4:$B$2003,$A7)=0,"-",SUMIFS('Daily Entry'!$M$4:$M$2003,'Daily Entry'!$A$4:$A$2003,$D$1,'Daily Entry'!$B$4:$B$2003,$A7))) -> 27 | L7: =IF($A7="","",IF(COUNTIFS('Daily Entry'!$A$4:$A$2003,$D$1,'Daily Entry'!$B$4:$B$2003,$A7)=0,"-",SUMIFS('Daily Entry'!$O$4:$O$2003,'Daily Entry'!$A$4:$A$2003,$D$1,'Daily Entry'!$B$4:$B$2003,$A7))) -> 1000 | M7: =IF($A7="","",IF(COUNTIFS('Daily Entry'!$A$4:$A$2003,$D$1,'Daily Entry'!$B$4:$B$2003,$A7)=0,"-",SUMIFS('Daily Entry'!$N$4:$N$2003,'Daily Entry'!$A$4:$A$2003,$D$1,'Daily Entry'!$B$4:$B$2003,$A7))) -> 60 | N7: =IF($A7="","",IF(COUNTIFS('Daily Entry'!$A$4:$A$2003,$D$1,'Daily Entry'!$B$4:$B$2003,$A7)=0,"-",SUMIFS('Daily Entry'!$P$4:$P$2003,'Daily Entry'!$A$4:$A$2003,$D$1,'Daily Entry'!$B$4:$B$2003,$A7))) -> 60000 | O7: =IF($A7="","",IF(COUNTIFS('Daily Entry'!$A$4:$A$2003,$D$1,'Daily Entry'!$B$4:$B$2003,$A7)=0,"-",SUMIFS('Daily Entry'!$R$4:$R$2003,'Daily Entry'!$A$4:$A$2003,$D$1,'Daily Entry'!$B$4:$B$2003,$A7))) -> 17500
A8: =IF(Drinks!$A7="","",Drinks!$A7) -> Castel Beer | B8: =IF($A8="","",IF(COUNTIFS('Daily Entry'!$A$4:$A$2003,$D$1,'Daily Entry'!$B$4:$B$2003,$A8)=0,"-",SUMIFS('Daily Entry'!$C$4:$C$2003,'Daily Entry'!$A$4:$A$2003,$D$1,'Daily Entry'!$B$4:$B$2003,$A8))) -> 0 | C8: =IF($A8="","",IF(COUNTIFS('Daily Entry'!$A$4:$A$2003,$D$1,'Daily Entry'!$B$4:$B$2003,$A8)=0,"-",SUMIFS('Daily Entry'!$D$4:$D$2003,'Daily Entry'!$A$4:$A$2003,$D$1,'Daily Entry'!$B$4:$B$2003,$A8))) -> 5 | D8: =IF($A8="","",IF(COUNTIFS('Daily Entry'!$A$4:$A$2003,$D$1,'Daily Entry'!$B$4:$B$2003,$A8)=0,"-",SUMIFS('Daily Entry'!$F$4:$F$2003,'Daily Entry'!$A$4:$A$2003,$D$1,'Daily Entry'!$B$4:$B$2003,$A8))) -> 0 | E8: =IF($A8="","",IF(COUNTIFS('Daily Entry'!$A$4:$A$2003,$D$1,'Daily Entry'!$B$4:$B$2003,$A8)=0,"-",SUMIFS('Daily Entry'!$E$4:$E$2003,'Daily Entry'!$A$4:$A$2003,$D$1,'Daily Entry'!$B$4:$B$2003,$A8))) -> 5 | F8: =IF($A8="","",IF(COUNTIFS('Daily Entry'!$A$4:$A$2003,$D$1,'Daily Entry'!$B$4:$B$2003,$A8)=0,"-",SUMIFS('Daily Entry'!$G$4:$G$2003,'Daily Entry'!$A$4:$A$2003,$D$1,'Daily Entry'!$B$4:$B$2003,$A8))) -> 8500 | G8: =IF($A8="","",IF(COUNTIFS('Daily Entry'!$A$4:$A$2003,$D$1,'Daily Entry'!$B$4:$B$2003,$A8)=0,"-",SUMIFS('Daily Entry'!$I$4:$I$2003,'Daily Entry'!$A$4:$A$2003,$D$1,'Daily Entry'!$B$4:$B$2003,$A8))) -> 0 | H8: =IF($A8="","",IF(COUNTIFS('Daily Entry'!$A$4:$A$2003,$D$1,'Daily Entry'!$B$4:$B$2003,$A8)=0,"-",SUMIFS('Daily Entry'!$J$4:$J$2003,'Daily Entry'!$A$4:$A$2003,$D$1,'Daily Entry'!$B$4:$B$2003,$A8))) -> 16 | I8: =IF($A8="","",IF(COUNTIFS('Daily Entry'!$A$4:$A$2003,$D$1,'Daily Entry'!$B$4:$B$2003,$A8)=0,"-",SUMIFS('Daily Entry'!$K$4:$K$2003,'Daily Entry'!$A$4:$A$2003,$D$1,'Daily Entry'!$B$4:$B$2003,$A8))) -> 60 | J8: =IF($A8="","",IF(COUNTIFS('Daily Entry'!$A$4:$A$2003,$D$1,'Daily Entry'!$B$4:$B$2003,$A8)=0,"-",SUMIFS('Daily Entry'!$L$4:$L$2003,'Daily Entry'!$A$4:$A$2003,$D$1,'Daily Entry'!$B$4:$B$2003,$A8))) -> 76 | K8: =IF($A8="","",IF(COUNTIFS('Daily Entry'!$A$4:$A$2003,$D$1,'Daily Entry'!$B$4:$B$2003,$A8)=0,"-",SUMIFS('Daily Entry'!$M$4:$M$2003,'Daily Entry'!$A$4:$A$2003,$D$1,'Daily Entry'!$B$4:$B$2003,$A8))) -> 57 | L8: =IF($A8="","",IF(COUNTIFS('Daily Entry'!$A$4:$A$2003,$D$1,'Daily Entry'!$B$4:$B$2003,$A8)=0,"-",SUMIFS('Daily Entry'!$O$4:$O$2003,'Daily Entry'!$A$4:$A$2003,$D$1,'Daily Entry'!$B$4:$B$2003,$A8))) -> 1000 | M8: =IF($A8="","",IF(COUNTIFS('Daily Entry'!$A$4:$A$2003,$D$1,'Daily Entry'!$B$4:$B$2003,$A8)=0,"-",SUMIFS('Daily Entry'!$N$4:$N$2003,'Daily Entry'!$A$4:$A$2003,$D$1,'Daily Entry'!$B$4:$B$2003,$A8))) -> 19 | N8: =IF($A8="","",IF(COUNTIFS('Daily Entry'!$A$4:$A$2003,$D$1,'Daily Entry'!$B$4:$B$2003,$A8)=0,"-",SUMIFS('Daily Entry'!$P$4:$P$2003,'Daily Entry'!$A$4:$A$2003,$D$1,'Daily Entry'!$B$4:$B$2003,$A8))) -> 19000 | O8: =IF($A8="","",IF(COUNTIFS('Daily Entry'!$A$4:$A$2003,$D$1,'Daily Entry'!$B$4:$B$2003,$A8)=0,"-",SUMIFS('Daily Entry'!$R$4:$R$2003,'Daily Entry'!$A$4:$A$2003,$D$1,'Daily Entry'!$B$4:$B$2003,$A8))) -> 5541.6667
A9: =IF(Drinks!$A8="","",Drinks!$A8) -> Castel Milk | B9: =IF($A9="","",IF(COUNTIFS('Daily Entry'!$A$4:$A$2003,$D$1,'Daily Entry'!$B$4:$B$2003,$A9)=0,"-",SUMIFS('Daily Entry'!$C$4:$C$2003,'Daily Entry'!$A$4:$A$2003,$D$1,'Daily Entry'!$B$4:$B$2003,$A9))) -> 4 | C9: =IF($A9="","",IF(COUNTIFS('Daily Entry'!$A$4:$A$2003,$D$1,'Daily Entry'!$B$4:$B$2003,$A9)=0,"-",SUMIFS('Daily Entry'!$D$4:$D$2003,'Daily Entry'!$A$4:$A$2003,$D$1,'Daily Entry'!$B$4:$B$2003,$A9))) -> 3 | D9: =IF($A9="","",IF(COUNTIFS('Daily Entry'!$A$4:$A$2003,$D$1,'Daily Entry'!$B$4:$B$2003,$A9)=0,"-",SUMIFS('Daily Entry'!$F$4:$F$2003,'Daily Entry'!$A$4:$A$2003,$D$1,'Daily Entry'!$B$4:$B$2003,$A9))) -> 4 | E9: =IF($A9="","",IF(COUNTIFS('Daily Entry'!$A$4:$A$2003,$D$1,'Daily Entry'!$B$4:$B$2003,$A9)=0,"-",SUMIFS('Daily Entry'!$E$4:$E$2003,'Daily Entry'!$A$4:$A$2003,$D$1,'Daily Entry'!$B$4:$B$2003,$A9))) -> 3 | F9: =IF($A9="","",IF(COUNTIFS('Daily Entry'!$A$4:$A$2003,$D$1,'Daily Entry'!$B$4:$B$2003,$A9)=0,"-",SUMIFS('Daily Entry'!$G$4:$G$2003,'Daily Entry'!$A$4:$A$2003,$D$1,'Daily Entry'!$B$4:$B$2003,$A9))) -> 8500 | G9: =IF($A9="","",IF(COUNTIFS('Daily Entry'!$A$4:$A$2003,$D$1,'Daily Entry'!$B$4:$B$2003,$A9)=0,"-",SUMIFS('Daily Entry'!$I$4:$I$2003,'Daily Entry'!$A$4:$A$2003,$D$1,'Daily Entry'!$B$4:$B$2003,$A9))) -> 34000 | H9: =IF($A9="","",IF(COUNTIFS('Daily Entry'!$A$4:$A$2003,$D$1,'Daily Entry'!$B$4:$B$2003,$A9)=0,"-",SUMIFS('Daily Entry'!$J$4:$J$2003,'Daily Entry'!$A$4:$A$2003,$D$1,'Daily Entry'!$B$4:$B$2003,$A9))) -> 0 | I9: =IF($A9="","",IF(COUNTIFS('Daily Entry'!$A$4:$A$2003,$D$1,'Daily Entry'!$B$4:$B$2003,$A9)=0,"-",SUMIFS('Daily Entry'!$K$4:$K$2003,'Daily Entry'!$A$4:$A$2003,$D$1,'Daily Entry'!$B$4:$B$2003,$A9))) -> 36 | J9: =IF($A9="","",IF(COUNTIFS('Daily Entry'!$A$4:$A$2003,$D$1,'Daily Entry'!$B$4:$B$2003,$A9)=0,"-",SUMIFS('Daily Entry'!$L$4:$L$2003,'Daily Entry'!$A$4:$A$2003,$D$1,'Daily Entry'!$B$4:$B$2003,$A9))) -> 36 | K9: =IF($A9="","",IF(COUNTIFS('Daily Entry'!$A$4:$A$2003,$D$1,'Daily Entry'!$B$4:$B$2003,$A9)=0,"-",SUMIFS('Daily Entry'!$M$4:$M$2003,'Daily Entry'!$A$4:$A$2003,$D$1,'Daily Entry'!$B$4:$B$2003,$A9))) -> 34 | L9: =IF($A9="","",IF(COUNTIFS('Daily Entry'!$A$4:$A$2003,$D$1,'Daily Entry'!$B$4:$B$2003,$A9)=0,"-",SUMIFS('Daily Entry'!$O$4:$O$2003,'Daily Entry'!$A$4:$A$2003,$D$1,'Daily Entry'!$B$4:$B$2003,$A9))) -> 1000 | M9: =IF($A9="","",IF(COUNTIFS('Daily Entry'!$A$4:$A$2003,$D$1,'Daily Entry'!$B$4:$B$2003,$A9)=0,"-",SUMIFS('Daily Entry'!$N$4:$N$2003,'Daily Entry'!$A$4:$A$2003,$D$1,'Daily Entry'!$B$4:$B$2003,$A9))) -> 2 | N9: =IF($A9="","",IF(COUNTIFS('Daily Entry'!$A$4:$A$2003,$D$1,'Daily Entry'!$B$4:$B$2003,$A9)=0,"-",SUMIFS('Daily Entry'!$P$4:$P$2003,'Daily Entry'!$A$4:$A$2003,$D$1,'Daily Entry'!$B$4:$B$2003,$A9))) -> 2000 | O9: =IF($A9="","",IF(COUNTIFS('Daily Entry'!$A$4:$A$2003,$D$1,'Daily Entry'!$B$4:$B$2003,$A9)=0,"-",SUMIFS('Daily Entry'!$R$4:$R$2003,'Daily Entry'!$A$4:$A$2003,$D$1,'Daily Entry'!$B$4:$B$2003,$A9))) -> 583.33333
